<?xml version="1.0" ?>
<sdf version="1.8">
    <model name='vehicle_blue' canonical_link='chassis'>

        <!-- ===================== CHASSIS ===================== -->
        <link name='chassis'>
            <!-- Adjusted because the body length was reduced -->
            <pose relative_to='__model__'>0.25 0 0.28 0 0 0</pose>

            <!-- Inertial properties -->
            <inertial>
                <mass>1.14395</mass>
                <inertia>
                    <ixx>0.095329</ixx>
                    <ixy>0</ixy>
                    <ixz>0</ixz>
                    <iyy>0.381317</iyy>
                    <iyz>0</iyz>
                    <izz>0.476646</izz>
                </inertia>
            </inertial>

            <!-- Visual shape of chassis -->
            <visual name='visual'>
                <geometry>
                    <!-- Shortened body: 1.0 x 0.7 x 0.35 -->
                    <box>
                        <size>1.0 0.7 0.35</size>
                    </box>
                </geometry>
                <material>
                    <ambient>0.0 0.0 1.0 1</ambient>
                    <diffuse>0.0 0.0 1.0 1</diffuse>
                    <specular>0.0 0.0 1.0 1</specular>
                </material>
            </visual>

            <!-- Collision shape of chassis -->
            <collision name='collision'>
                <geometry>
                    <box>
                        <size>1.0 0.7 0.35</size>
                    </box>
                </geometry>
            </collision>
        </link>

        <!-- ===================== LEFT WHEEL ===================== -->
        <link name='left_wheel'>
            <!-- Scaled 0.7 and position adjusted -->
            <pose relative_to="chassis">-0.35 0.42 0 -1.5707 0 0</pose>

            <!-- Inertial properties -->
            <inertial>
                <mass>1</mass>
                <inertia>
                    <ixx>0.043333</ixx>
                    <ixy>0</ixy>
                    <ixz>0</ixz>
                    <iyy>0.043333</iyy>
                    <iyz>0</iyz>
                    <izz>0.08</izz>
                </inertia>
            </inertial>

            <!-- Visual shape -->
            <visual name='visual'>
                <geometry>
                    <cylinder>
                        <radius>0.28</radius>
                        <length>0.14</length>
                    </cylinder>
                </geometry>
                <material>
                    <ambient>1.0 0.0 0.0 1</ambient>
                    <diffuse>1.0 0.0 0.0 1</diffuse>
                    <specular>1.0 0.0 0.0 1</specular>
                </material>
            </visual>

            <!-- Collision shape -->
            <collision name='collision'>
                <geometry>
                    <cylinder>
                        <radius>0.28</radius>
                        <length>0.14</length>
                    </cylinder>
                </geometry>
            </collision>
        </link>

        <!-- ===================== RIGHT WHEEL ===================== -->
        <link name='right_wheel'>
            <pose relative_to="chassis">-0.35 -0.42 0 -1.5707 0 0</pose>

            <inertial>
                <mass>1</mass>
                <inertia>
                    <ixx>0.043333</ixx>
                    <ixy>0</ixy>
                    <ixz>0</ixz>
                    <iyy>0.043333</iyy>
                    <iyz>0</iyz>
                    <izz>0.08</izz>
                </inertia>
            </inertial>

            <visual name='visual'>
                <geometry>
                    <cylinder>
                        <radius>0.28</radius>
                        <length>0.14</length>
                    </cylinder>
                </geometry>
                <material>
                    <ambient>1.0 0.0 0.0 1</ambient>
                    <diffuse>1.0 0.0 0.0 1</diffuse>
                    <specular>1.0 0.0 0.0 1</specular>
                </material>
            </visual>

            <collision name='collision'>
                <geometry>
                    <cylinder>
                        <radius>0.28</radius>
                        <length>0.14</length>
                    </cylinder>
                </geometry>
            </collision>
        </link>

        <!-- ===================== CASTER FRAME ===================== -->
        <frame name="caster_frame" attached_to='chassis'>
            <!-- Moved slightly backward due to shortened body -->
            <pose>0.4 0 -0.14 0 0 0</pose>
        </frame>

        <!-- ===================== CASTER WHEEL ===================== -->
        <link name='caster'>
            <pose relative_to='caster_frame'/>

            <inertial>
                <mass>1</mass>
                <inertia>
                    <ixx>0.016</ixx>
                    <ixy>0</ixy>
                    <ixz>0</ixz>
                    <iyy>0.016</iyy>
                    <iyz>0</iyz>
                    <izz>0.016</izz>
                </inertia>
            </inertial>

            <visual name='visual'>
                <geometry>
                    <sphere>
                        <radius>0.14</radius>
                    </sphere>
                </geometry>
                <material>
                    <ambient>0.0 1 0.0 1</ambient>
                    <diffuse>0.0 1 0.0 1</diffuse>
                    <specular>0.0 1 0.0 1</specular>
                </material>
            </visual>

            <collision name='collision'>
                <geometry>
                    <sphere>
                        <radius>0.14</radius>
                    </sphere>
                </geometry>
            </collision>
        </link>

        <!-- ===================== JOINTS ===================== -->

        <!-- Left wheel joint -->
        <joint name='left_wheel_joint' type='revolute'>
            <pose relative_to='left_wheel'/>
            <parent>chassis</parent>
            <child>left_wheel</child>
            <axis>
                <xyz expressed_in='__model__'>0 1 0</xyz>
                <limit>
                    <lower>-1.79769e+308</lower>
                    <upper>1.79769e+308</upper>
                </limit>
            </axis>
        </joint>

        <!-- Right wheel joint -->
        <joint name='right_wheel_joint' type='revolute'>
            <pose relative_to='right_wheel'/>
            <parent>chassis</parent>
            <child>right_wheel</child>
            <axis>
                <xyz expressed_in='__model__'>0 1 0</xyz>
                <limit>
                    <lower>-1.79769e+308</lower>
                    <upper>1.79769e+308</upper>
                </limit>
            </axis>
        </joint>

        <!-- Caster joint (ball joint) -->
        <joint name='caster_wheel' type='ball'>
            <parent>chassis</parent>
            <child>caster</child>
        </joint>

        <!-- ===================== DIFF DRIVE PLUGIN ===================== -->
        <plugin
            filename="libignition-gazebo-diff-drive-system.so"
            name="ignition::gazebo::systems::DiffDrive">
            <left_joint>left_wheel_joint</left_joint>
            <right_joint>right_wheel_joint</right_joint>

            <!-- Updated according to 0.7x scale -->
            <wheel_separation>0.84</wheel_separation>
            <wheel_radius>0.28</wheel_radius>

            <odom_publish_frequency>1</odom_publish_frequency>
            <topic>cmd_vel2</topic>
        </plugin>

    </model>
</sdf>
